Internal Server Error: /api/register/
Internal Server Error: /api/register/
{'username': [ErrorDetail(string='A user with that username already exists.', code='unique')], 'email': [ErrorDetail(string='user with this email already exists.', code='unique')]}
Internal Server Error: /api/register/
Traceback (most recent call last):
  File "C:\Users\goliy\Desktop\Developpeur Data IA P2\Course Django\django rest course\venv\Lib\site-packages\django\core\handlers\exception.py", line 55, in inner
    response = get_response(request)
               ^^^^^^^^^^^^^^^^^^^^^
  File "C:\Users\goliy\Desktop\Developpeur Data IA P2\Course Django\django rest course\venv\Lib\site-packages\django\core\handlers\base.py", line 197, in _get_response
    response = wrapped_callback(request, *callback_args, **callback_kwargs)
               ^^^^^^^^^^^^^^^^^^^^^^^^^^^^^^^^^^^^^^^^^^^^^^^^^^^^^^^^^^^^
  File "C:\Users\goliy\Desktop\Developpeur Data IA P2\Course Django\django rest course\venv\Lib\site-packages\django\views\decorators\csrf.py", line 65, in _view_wrapper
    return view_func(request, *args, **kwargs)
           ^^^^^^^^^^^^^^^^^^^^^^^^^^^^^^^^^^^
  File "C:\Users\goliy\Desktop\Developpeur Data IA P2\Course Django\django rest course\venv\Lib\site-packages\django\views\generic\base.py", line 104, in view
    return self.dispatch(request, *args, **kwargs)
           ^^^^^^^^^^^^^^^^^^^^^^^^^^^^^^^^^^^^^^^
  File "C:\Users\goliy\Desktop\Developpeur Data IA P2\Course Django\django rest course\venv\Lib\site-packages\rest_framework\views.py", line 511, in dispatch
    self.response = self.finalize_response(request, response, *args, **kwargs)
                    ^^^^^^^^^^^^^^^^^^^^^^^^^^^^^^^^^^^^^^^^^^^^^^^^^^^^^^^^^^
  File "C:\Users\goliy\Desktop\Developpeur Data IA P2\Course Django\django rest course\venv\Lib\site-packages\rest_framework\views.py", line 423, in finalize_response
    assert isinstance(response, HttpResponseBase), (
AssertionError: Expected a `Response`, `HttpResponse` or `StreamingHttpResponse` to be returned from the view, but received a `<class 'NoneType'>`
Internal Server Error: /api/register/
Traceback (most recent call last):
  File "C:\Users\goliy\Desktop\Developpeur Data IA P2\Course Django\django rest course\venv\Lib\site-packages\django\core\handlers\exception.py", line 55, in inner
    response = get_response(request)
               ^^^^^^^^^^^^^^^^^^^^^
  File "C:\Users\goliy\Desktop\Developpeur Data IA P2\Course Django\django rest course\venv\Lib\site-packages\django\core\handlers\base.py", line 197, in _get_response
    response = wrapped_callback(request, *callback_args, **callback_kwargs)
               ^^^^^^^^^^^^^^^^^^^^^^^^^^^^^^^^^^^^^^^^^^^^^^^^^^^^^^^^^^^^
  File "C:\Users\goliy\Desktop\Developpeur Data IA P2\Course Django\django rest course\venv\Lib\site-packages\django\views\decorators\csrf.py", line 65, in _view_wrapper
    return view_func(request, *args, **kwargs)
           ^^^^^^^^^^^^^^^^^^^^^^^^^^^^^^^^^^^
  File "C:\Users\goliy\Desktop\Developpeur Data IA P2\Course Django\django rest course\venv\Lib\site-packages\django\views\generic\base.py", line 104, in view
    return self.dispatch(request, *args, **kwargs)
           ^^^^^^^^^^^^^^^^^^^^^^^^^^^^^^^^^^^^^^^
  File "C:\Users\goliy\Desktop\Developpeur Data IA P2\Course Django\django rest course\venv\Lib\site-packages\rest_framework\views.py", line 511, in dispatch
    self.response = self.finalize_response(request, response, *args, **kwargs)
                    ^^^^^^^^^^^^^^^^^^^^^^^^^^^^^^^^^^^^^^^^^^^^^^^^^^^^^^^^^^
  File "C:\Users\goliy\Desktop\Developpeur Data IA P2\Course Django\django rest course\venv\Lib\site-packages\rest_framework\views.py", line 423, in finalize_response
    assert isinstance(response, HttpResponseBase), (
AssertionError: Expected a `Response`, `HttpResponse` or `StreamingHttpResponse` to be returned from the view, but received a `<class 'NoneType'>`
Internal Server Error: /api/register/
Traceback (most recent call last):
  File "C:\Users\goliy\Desktop\Developpeur Data IA P2\Course Django\django rest course\venv\Lib\site-packages\django\core\handlers\exception.py", line 55, in inner
    response = get_response(request)
               ^^^^^^^^^^^^^^^^^^^^^
  File "C:\Users\goliy\Desktop\Developpeur Data IA P2\Course Django\django rest course\venv\Lib\site-packages\django\core\handlers\base.py", line 197, in _get_response
    response = wrapped_callback(request, *callback_args, **callback_kwargs)
               ^^^^^^^^^^^^^^^^^^^^^^^^^^^^^^^^^^^^^^^^^^^^^^^^^^^^^^^^^^^^
  File "C:\Users\goliy\Desktop\Developpeur Data IA P2\Course Django\django rest course\venv\Lib\site-packages\django\views\decorators\csrf.py", line 65, in _view_wrapper
    return view_func(request, *args, **kwargs)
           ^^^^^^^^^^^^^^^^^^^^^^^^^^^^^^^^^^^
  File "C:\Users\goliy\Desktop\Developpeur Data IA P2\Course Django\django rest course\venv\Lib\site-packages\django\views\generic\base.py", line 104, in view
    return self.dispatch(request, *args, **kwargs)
           ^^^^^^^^^^^^^^^^^^^^^^^^^^^^^^^^^^^^^^^
  File "C:\Users\goliy\Desktop\Developpeur Data IA P2\Course Django\django rest course\venv\Lib\site-packages\rest_framework\views.py", line 509, in dispatch
    response = self.handle_exception(exc)
               ^^^^^^^^^^^^^^^^^^^^^^^^^^
  File "C:\Users\goliy\Desktop\Developpeur Data IA P2\Course Django\django rest course\venv\Lib\site-packages\rest_framework\views.py", line 469, in handle_exception
    self.raise_uncaught_exception(exc)
  File "C:\Users\goliy\Desktop\Developpeur Data IA P2\Course Django\django rest course\venv\Lib\site-packages\rest_framework\views.py", line 480, in raise_uncaught_exception
    raise exc
  File "C:\Users\goliy\Desktop\Developpeur Data IA P2\Course Django\django rest course\venv\Lib\site-packages\rest_framework\views.py", line 506, in dispatch
    response = handler(request, *args, **kwargs)
               ^^^^^^^^^^^^^^^^^^^^^^^^^^^^^^^^^
  File "C:\Users\goliy\Desktop\Developpeur Data IA P2\Course Django\django rest course\venv\Lib\site-packages\rest_framework\decorators.py", line 50, in handler
    return func(*args, **kwargs)
           ^^^^^^^^^^^^^^^^^^^^^
  File "C:\Users\goliy\Desktop\Developpeur Data IA P2\Course Django\django rest course\accounts\views.py", line 70, in register_user
    confirm_password = data['confirm_password']
                       ~~~~^^^^^^^^^^^^^^^^^^^^
KeyError: 'confirm_password'
Internal Server Error: /api/register/
Traceback (most recent call last):
  File "C:\Users\goliy\Desktop\Developpeur Data IA P2\Course Django\django rest course\venv\Lib\site-packages\django\core\handlers\exception.py", line 55, in inner
    response = get_response(request)
               ^^^^^^^^^^^^^^^^^^^^^
  File "C:\Users\goliy\Desktop\Developpeur Data IA P2\Course Django\django rest course\venv\Lib\site-packages\django\core\handlers\base.py", line 197, in _get_response
    response = wrapped_callback(request, *callback_args, **callback_kwargs)
               ^^^^^^^^^^^^^^^^^^^^^^^^^^^^^^^^^^^^^^^^^^^^^^^^^^^^^^^^^^^^
  File "C:\Users\goliy\Desktop\Developpeur Data IA P2\Course Django\django rest course\venv\Lib\site-packages\django\views\decorators\csrf.py", line 65, in _view_wrapper
    return view_func(request, *args, **kwargs)
           ^^^^^^^^^^^^^^^^^^^^^^^^^^^^^^^^^^^
  File "C:\Users\goliy\Desktop\Developpeur Data IA P2\Course Django\django rest course\venv\Lib\site-packages\django\views\generic\base.py", line 104, in view
    return self.dispatch(request, *args, **kwargs)
           ^^^^^^^^^^^^^^^^^^^^^^^^^^^^^^^^^^^^^^^
  File "C:\Users\goliy\Desktop\Developpeur Data IA P2\Course Django\django rest course\venv\Lib\site-packages\rest_framework\views.py", line 509, in dispatch
    response = self.handle_exception(exc)
               ^^^^^^^^^^^^^^^^^^^^^^^^^^
  File "C:\Users\goliy\Desktop\Developpeur Data IA P2\Course Django\django rest course\venv\Lib\site-packages\rest_framework\views.py", line 469, in handle_exception
    self.raise_uncaught_exception(exc)
  File "C:\Users\goliy\Desktop\Developpeur Data IA P2\Course Django\django rest course\venv\Lib\site-packages\rest_framework\views.py", line 480, in raise_uncaught_exception
    raise exc
  File "C:\Users\goliy\Desktop\Developpeur Data IA P2\Course Django\django rest course\venv\Lib\site-packages\rest_framework\views.py", line 506, in dispatch
    response = handler(request, *args, **kwargs)
               ^^^^^^^^^^^^^^^^^^^^^^^^^^^^^^^^^
  File "C:\Users\goliy\Desktop\Developpeur Data IA P2\Course Django\django rest course\venv\Lib\site-packages\rest_framework\decorators.py", line 50, in handler
    return func(*args, **kwargs)
           ^^^^^^^^^^^^^^^^^^^^^
  File "C:\Users\goliy\Desktop\Developpeur Data IA P2\Course Django\django rest course\accounts\views.py", line 66, in register_user
    if validate_email(email):
                      ^^^^^
UnboundLocalError: cannot access local variable 'email' where it is not associated with a value
Internal Server Error: /api/register/
Traceback (most recent call last):
  File "C:\Users\goliy\Desktop\Developpeur Data IA P2\Course Django\django rest course\venv\Lib\site-packages\django\core\handlers\exception.py", line 55, in inner
    response = get_response(request)
               ^^^^^^^^^^^^^^^^^^^^^
  File "C:\Users\goliy\Desktop\Developpeur Data IA P2\Course Django\django rest course\venv\Lib\site-packages\django\core\handlers\base.py", line 197, in _get_response
    response = wrapped_callback(request, *callback_args, **callback_kwargs)
               ^^^^^^^^^^^^^^^^^^^^^^^^^^^^^^^^^^^^^^^^^^^^^^^^^^^^^^^^^^^^
  File "C:\Users\goliy\Desktop\Developpeur Data IA P2\Course Django\django rest course\venv\Lib\site-packages\django\views\decorators\csrf.py", line 65, in _view_wrapper
    return view_func(request, *args, **kwargs)
           ^^^^^^^^^^^^^^^^^^^^^^^^^^^^^^^^^^^
  File "C:\Users\goliy\Desktop\Developpeur Data IA P2\Course Django\django rest course\venv\Lib\site-packages\django\views\generic\base.py", line 104, in view
    return self.dispatch(request, *args, **kwargs)
           ^^^^^^^^^^^^^^^^^^^^^^^^^^^^^^^^^^^^^^^
  File "C:\Users\goliy\Desktop\Developpeur Data IA P2\Course Django\django rest course\venv\Lib\site-packages\rest_framework\views.py", line 509, in dispatch
    response = self.handle_exception(exc)
               ^^^^^^^^^^^^^^^^^^^^^^^^^^
  File "C:\Users\goliy\Desktop\Developpeur Data IA P2\Course Django\django rest course\venv\Lib\site-packages\rest_framework\views.py", line 469, in handle_exception
    self.raise_uncaught_exception(exc)
  File "C:\Users\goliy\Desktop\Developpeur Data IA P2\Course Django\django rest course\venv\Lib\site-packages\rest_framework\views.py", line 480, in raise_uncaught_exception
    raise exc
  File "C:\Users\goliy\Desktop\Developpeur Data IA P2\Course Django\django rest course\venv\Lib\site-packages\rest_framework\views.py", line 506, in dispatch
    response = handler(request, *args, **kwargs)
               ^^^^^^^^^^^^^^^^^^^^^^^^^^^^^^^^^
  File "C:\Users\goliy\Desktop\Developpeur Data IA P2\Course Django\django rest course\venv\Lib\site-packages\rest_framework\decorators.py", line 50, in handler
    return func(*args, **kwargs)
           ^^^^^^^^^^^^^^^^^^^^^
  File "C:\Users\goliy\Desktop\Developpeur Data IA P2\Course Django\django rest course\accounts\views.py", line 66, in register_user
    if validate_email(email):
                      ^^^^^
UnboundLocalError: cannot access local variable 'email' where it is not associated with a value
Internal Server Error: /api/register/
Traceback (most recent call last):
  File "C:\Users\goliy\Desktop\Developpeur Data IA P2\Course Django\django rest course\venv\Lib\site-packages\django\core\handlers\exception.py", line 55, in inner
    response = get_response(request)
               ^^^^^^^^^^^^^^^^^^^^^
  File "C:\Users\goliy\Desktop\Developpeur Data IA P2\Course Django\django rest course\venv\Lib\site-packages\django\core\handlers\base.py", line 197, in _get_response
    response = wrapped_callback(request, *callback_args, **callback_kwargs)
               ^^^^^^^^^^^^^^^^^^^^^^^^^^^^^^^^^^^^^^^^^^^^^^^^^^^^^^^^^^^^
  File "C:\Users\goliy\Desktop\Developpeur Data IA P2\Course Django\django rest course\venv\Lib\site-packages\django\views\decorators\csrf.py", line 65, in _view_wrapper
    return view_func(request, *args, **kwargs)
           ^^^^^^^^^^^^^^^^^^^^^^^^^^^^^^^^^^^
  File "C:\Users\goliy\Desktop\Developpeur Data IA P2\Course Django\django rest course\venv\Lib\site-packages\django\views\generic\base.py", line 104, in view
    return self.dispatch(request, *args, **kwargs)
           ^^^^^^^^^^^^^^^^^^^^^^^^^^^^^^^^^^^^^^^
  File "C:\Users\goliy\Desktop\Developpeur Data IA P2\Course Django\django rest course\venv\Lib\site-packages\rest_framework\views.py", line 509, in dispatch
    response = self.handle_exception(exc)
               ^^^^^^^^^^^^^^^^^^^^^^^^^^
  File "C:\Users\goliy\Desktop\Developpeur Data IA P2\Course Django\django rest course\venv\Lib\site-packages\rest_framework\views.py", line 469, in handle_exception
    self.raise_uncaught_exception(exc)
  File "C:\Users\goliy\Desktop\Developpeur Data IA P2\Course Django\django rest course\venv\Lib\site-packages\rest_framework\views.py", line 480, in raise_uncaught_exception
    raise exc
  File "C:\Users\goliy\Desktop\Developpeur Data IA P2\Course Django\django rest course\venv\Lib\site-packages\rest_framework\views.py", line 506, in dispatch
    response = handler(request, *args, **kwargs)
               ^^^^^^^^^^^^^^^^^^^^^^^^^^^^^^^^^
  File "C:\Users\goliy\Desktop\Developpeur Data IA P2\Course Django\django rest course\venv\Lib\site-packages\rest_framework\decorators.py", line 50, in handler
    return func(*args, **kwargs)
           ^^^^^^^^^^^^^^^^^^^^^
  File "C:\Users\goliy\Desktop\Developpeur Data IA P2\Course Django\django rest course\accounts\views.py", line 66, in register_user
    if validate_email(email):
                      ^^^^^
UnboundLocalError: cannot access local variable 'email' where it is not associated with a value
Internal Server Error: /api/login/
Traceback (most recent call last):
  File "C:\Users\goliy\Desktop\Developpeur Data IA P2\Course Django\django rest course\venv\Lib\site-packages\django\core\handlers\exception.py", line 55, in inner
    response = get_response(request)
               ^^^^^^^^^^^^^^^^^^^^^
  File "C:\Users\goliy\Desktop\Developpeur Data IA P2\Course Django\django rest course\venv\Lib\site-packages\django\core\handlers\base.py", line 220, in _get_response
    response = response.render()
               ^^^^^^^^^^^^^^^^^
  File "C:\Users\goliy\Desktop\Developpeur Data IA P2\Course Django\django rest course\venv\Lib\site-packages\django\template\response.py", line 114, in render
    self.content = self.rendered_content
                   ^^^^^^^^^^^^^^^^^^^^^
  File "C:\Users\goliy\Desktop\Developpeur Data IA P2\Course Django\django rest course\venv\Lib\site-packages\rest_framework\response.py", line 74, in rendered_content
    ret = renderer.render(self.data, accepted_media_type, context)
          ^^^^^^^^^^^^^^^^^^^^^^^^^^^^^^^^^^^^^^^^^^^^^^^^^^^^^^^^
  File "C:\Users\goliy\Desktop\Developpeur Data IA P2\Course Django\django rest course\venv\Lib\site-packages\rest_framework\renderers.py", line 99, in render
    ret = json.dumps(
          ^^^^^^^^^^^
  File "C:\Users\goliy\Desktop\Developpeur Data IA P2\Course Django\django rest course\venv\Lib\site-packages\rest_framework\utils\json.py", line 25, in dumps
    return json.dumps(*args, **kwargs)
           ^^^^^^^^^^^^^^^^^^^^^^^^^^^
  File "C:\Users\goliy\AppData\Local\Programs\Python\Python312\Lib\json\__init__.py", line 238, in dumps
    **kw).encode(obj)
          ^^^^^^^^^^^
  File "C:\Users\goliy\AppData\Local\Programs\Python\Python312\Lib\json\encoder.py", line 200, in encode
    chunks = self.iterencode(o, _one_shot=True)
             ^^^^^^^^^^^^^^^^^^^^^^^^^^^^^^^^^^
  File "C:\Users\goliy\AppData\Local\Programs\Python\Python312\Lib\json\encoder.py", line 258, in iterencode
    return _iterencode(o, 0)
           ^^^^^^^^^^^^^^^^^
  File "C:\Users\goliy\Desktop\Developpeur Data IA P2\Course Django\django rest course\venv\Lib\site-packages\rest_framework\utils\encoders.py", line 67, in default
    return super().default(obj)
           ^^^^^^^^^^^^^^^^^^^^
  File "C:\Users\goliy\AppData\Local\Programs\Python\Python312\Lib\json\encoder.py", line 180, in default
    raise TypeError(f'Object of type {o.__class__.__name__} '
TypeError: Object of type User is not JSON serializable
